<sdf version='1.7'>
  <world name='default'>
    <light name='sun' type='directional'>
      <cast_shadows>1</cast_shadows>
      <pose>0 0 10 0 -0 0</pose>
      <diffuse>0.8 0.8 0.8 1</diffuse>
      <specular>0.2 0.2 0.2 1</specular>
      <attenuation>
        <range>1000</range>
        <constant>0.9</constant>
        <linear>0.01</linear>
        <quadratic>0.001</quadratic>
      </attenuation>
      <direction>-0.5 0.1 -0.9</direction>
      <spot>
        <inner_angle>0</inner_angle>
        <outer_angle>0</outer_angle>
        <falloff>0</falloff>
      </spot>
    </light>
    <model name='ground_plane'>
      <static>1</static>
      <link name='link'>
        <collision name='collision'>
          <geometry>
            <plane>
              <normal>0 0 1</normal>
              <size>100 100</size>
            </plane>
          </geometry>
          <surface>
            <friction>
              <ode>
                <mu>100</mu>
                <mu2>50</mu2>
              </ode>
              <torsional>
                <ode/>
              </torsional>
            </friction>
            <contact>
              <ode/>
            </contact>
            <bounce/>
          </surface>
          <max_contacts>10</max_contacts>
        </collision>
        <visual name='visual'>
          <cast_shadows>0</cast_shadows>
          <geometry>
            <plane>
              <normal>0 0 1</normal>
              <size>100 100</size>
            </plane>
          </geometry>
          <material>
            <script>
              <uri>file://media/materials/scripts/gazebo.material</uri>
              <name>Gazebo/Grey</name>
            </script>
          </material>
        </visual>
        <self_collide>0</self_collide>
        <enable_wind>0</enable_wind>
        <kinematic>0</kinematic>
      </link>
    </model>
    <gravity>0 0 -9.8</gravity>
    <magnetic_field>6e-06 2.3e-05 -4.2e-05</magnetic_field>
    <atmosphere type='adiabatic'/>
    <physics type='ode'>
      <max_step_size>0.001</max_step_size>
      <real_time_factor>1</real_time_factor>
      <real_time_update_rate>1000</real_time_update_rate>
    </physics>
    <scene>
      <ambient>0.4 0.4 0.4 1</ambient>
      <background>0.7 0.7 0.7 1</background>
      <shadows>1</shadows>
    </scene>
    <audio>
      <device>default</device>
    </audio>
    <wind/>
    <spherical_coordinates>
      <surface_model>EARTH_WGS84</surface_model>
      <latitude_deg>0</latitude_deg>
      <longitude_deg>0</longitude_deg>
      <elevation>0</elevation>
      <heading_deg>0</heading_deg>
    </spherical_coordinates>
    <model name='arm'>
      <link name='ground'>
        <inertial>
          <pose>1e-06 -0.000621 0.028742 0 -0 0</pose>
          <mass>0.256153</mass>
          <inertia>
            <ixx>0.000371</ixx>
            <ixy>0</ixy>
            <ixz>0</ixz>
            <iyy>0.000377</iyy>
            <iyz>2e-06</iyz>
            <izz>0.000587</izz>
          </inertia>
        </inertial>
        <collision name='ground_fixed_joint_lump__base_link_collision'>
          <pose>0 0 0 0 -0 0</pose>
          <geometry>
            <mesh>
              <scale>0.001 0.001 0.001</scale>
              <uri>model://industrial_robot_arm/meshes/base_link.stl</uri>
            </mesh>
          </geometry>
          <max_contacts>10</max_contacts>
          <surface>
            <contact>
              <ode/>
            </contact>
            <bounce/>
            <friction>
              <torsional>
                <ode/>
              </torsional>
              <ode/>
            </friction>
          </surface>
        </collision>
        <visual name='ground_fixed_joint_lump__base_link_visual'>
          <pose>0 0 0 0 -0 0</pose>
          <geometry>
            <mesh>
              <scale>0.001 0.001 0.001</scale>
              <uri>model://industrial_robot_arm/meshes/base_link.stl</uri>
            </mesh>
          </geometry>
        </visual>
        <self_collide>0</self_collide>
        <enable_wind>0</enable_wind>
        <kinematic>0</kinematic>
      </link>
      <joint name='joint1' type='revolute'>
        <pose relative_to='ground'>0 0 0.05 0 -0 0</pose>
        <parent>ground</parent>
        <child>joint_1_1</child>
        <axis>
          <xyz>0 0 1</xyz>
          <limit>
            <lower>-1.5708</lower>
            <upper>1.5708</upper>
            <effort>100</effort>
            <velocity>100</velocity>
          </limit>
          <dynamics>
            <damping>10</damping>
            <friction>200</friction>
            <spring_reference>0</spring_reference>
            <spring_stiffness>0</spring_stiffness>
          </dynamics>
        </axis>
      </joint>
      <link name='joint_1_1'>
        <pose relative_to='joint1'>0 0 0 0 -0 0</pose>
        <inertial>
          <pose>-0.00264 0.002949 0.025731 0 -0 0</pose>
          <mass>0.220268</mass>
          <inertia>
            <ixx>0.000177</ixx>
            <ixy>-4e-06</ixy>
            <ixz>1.5e-05</ixz>
            <iyy>0.000243</iyy>
            <iyz>4e-06</iyz>
            <izz>0.000255</izz>
          </inertia>
        </inertial>
        <collision name='joint_1_1_collision'>
          <pose>0 0 -0.05 0 -0 0</pose>
          <geometry>
            <mesh>
              <scale>0.001 0.001 0.001</scale>
              <uri>model://industrial_robot_arm/meshes/joint_1_1.stl</uri>
            </mesh>
          </geometry>
          <max_contacts>10</max_contacts>
          <surface>
            <contact>
              <ode/>
            </contact>
            <bounce/>
            <friction>
              <torsional>
                <ode/>
              </torsional>
              <ode/>
            </friction>
          </surface>
        </collision>
        <visual name='joint_1_1_visual'>
          <pose>0 0 -0.05 0 -0 0</pose>
          <geometry>
            <mesh>
              <scale>0.001 0.001 0.001</scale>
              <uri>model://industrial_robot_arm/meshes/joint_1_1.stl</uri>
            </mesh>
          </geometry>
        </visual>
        <self_collide>0</self_collide>
        <enable_wind>0</enable_wind>
        <kinematic>0</kinematic>
      </link>
      <joint name='joint2' type='revolute'>
        <pose relative_to='joint_1_1'>-0.035 -0.017415 0.060054 0 -0 0</pose>
        <parent>joint_1_1</parent>
        <child>joint_2_LEFT_1</child>
        <axis>
          <xyz>-1 0 0</xyz>
          <limit>
            <lower>-1.5708</lower>
            <upper>1.5708</upper>
            <effort>100</effort>
            <velocity>100</velocity>
          </limit>
          <dynamics>
            <damping>10</damping>
            <friction>200</friction>
            <spring_reference>0</spring_reference>
            <spring_stiffness>0</spring_stiffness>
          </dynamics>
        </axis>
      </joint>
      <link name='joint_2_LEFT_1'>
        <pose relative_to='joint2'>0 0 0 0 -0 0</pose>
        <inertial>
          <pose>0.029736 0 0.040987 0 -0 0</pose>
          <mass>0.135879</mass>
          <inertia>
            <ixx>0.000242308</ixx>
            <ixy>-1.73252e-11</ixy>
            <ixz>5.11827e-06</ixz>
            <iyy>0.000262936</iyy>
            <iyz>3.70258e-12</iyz>
            <izz>5.06287e-05</izz>
          </inertia>
        </inertial>
        <collision name='joint_2_LEFT_1_collision'>
          <pose>0.035 0.017415 -0.110054 0 -0 0</pose>
          <geometry>
            <mesh>
              <scale>0.001 0.001 0.001</scale>
              <uri>model://industrial_robot_arm/meshes/joint_2_LEFT_1.stl</uri>
            </mesh>
          </geometry>
          <max_contacts>10</max_contacts>
          <surface>
            <contact>
              <ode/>
            </contact>
            <bounce/>
            <friction>
              <torsional>
                <ode/>
              </torsional>
              <ode/>
            </friction>
          </surface>
        </collision>
        <collision name='joint_2_LEFT_1_fixed_joint_lump__joint_2_RIGHT_1_collision_1'>
          <pose>0.035 0.017415 -0.110054 0 -0 0</pose>
          <geometry>
            <mesh>
              <scale>0.001 0.001 0.001</scale>
              <uri>model://industrial_robot_arm/meshes/joint_2_RIGHT_1.stl</uri>
            </mesh>
          </geometry>
          <max_contacts>10</max_contacts>
          <surface>
            <contact>
              <ode/>
            </contact>
            <bounce/>
            <friction>
              <torsional>
                <ode/>
              </torsional>
              <ode/>
            </friction>
          </surface>
        </collision>
        <visual name='joint_2_LEFT_1_visual'>
          <pose>0.035 0.017415 -0.110054 0 -0 0</pose>
          <geometry>
            <mesh>
              <scale>0.001 0.001 0.001</scale>
              <uri>model://industrial_robot_arm/meshes/joint_2_LEFT_1.stl</uri>
            </mesh>
          </geometry>
        </visual>
        <visual name='joint_2_LEFT_1_fixed_joint_lump__joint_2_RIGHT_1_visual_1'>
          <pose>0.035 0.017415 -0.110054 0 -0 0</pose>
          <geometry>
            <mesh>
              <scale>0.001 0.001 0.001</scale>
              <uri>model://industrial_robot_arm/meshes/joint_2_RIGHT_1.stl</uri>
            </mesh>
          </geometry>
        </visual>
        <self_collide>0</self_collide>
        <enable_wind>0</enable_wind>
        <kinematic>0</kinematic>
      </link>
      <joint name='joint3' type='revolute'>
        <pose relative_to='joint_2_LEFT_1'>0.01 0 0.12 0 -0 0</pose>
        <parent>joint_2_LEFT_1</parent>
        <child>joint_3_1</child>
        <axis>
          <xyz>-1 0 0</xyz>
          <limit>
            <lower>-1.5708</lower>
            <upper>1.5708</upper>
            <effort>100</effort>
            <velocity>100</velocity>
          </limit>
          <dynamics>
            <damping>10</damping>
            <friction>200</friction>
            <spring_reference>0</spring_reference>
            <spring_stiffness>0</spring_stiffness>
          </dynamics>
        </axis>
      </joint>
      <link name='joint_3_1'>
        <pose relative_to='joint3'>0 0 0 0 -0 0</pose>
        <inertial>
          <pose>0.022122 0.005605 0.037224 0 -0 0</pose>
          <mass>0.0718871</mass>
          <inertia>
            <ixx>5.4e-05</ixx>
            <ixy>-1e-06</ixy>
            <ixz>-2e-06</ixz>
            <iyy>4.2e-05</iyy>
            <iyz>-3e-06</iyz>
            <izz>4.2e-05</izz>
          </inertia>
        </inertial>
        <collision name='joint_3_1_collision'>
          <pose>0.025 0.017415 -0.230054 0 -0 0</pose>
          <geometry>
            <mesh>
              <scale>0.001 0.001 0.001</scale>
              <uri>model://industrial_robot_arm/meshes/joint_3_1.stl</uri>
            </mesh>
          </geometry>
          <max_contacts>10</max_contacts>
          <surface>
            <contact>
              <ode/>
            </contact>
            <bounce/>
            <friction>
              <torsional>
                <ode/>
              </torsional>
              <ode/>
            </friction>
          </surface>
        </collision>
        <visual name='joint_3_1_visual'>
          <pose>0.025 0.017415 -0.230054 0 -0 0</pose>
          <geometry>
            <mesh>
              <scale>0.001 0.001 0.001</scale>
              <uri>model://industrial_robot_arm/meshes/joint_3_1.stl</uri>
            </mesh>
          </geometry>
        </visual>
        <self_collide>0</self_collide>
        <enable_wind>0</enable_wind>
        <kinematic>0</kinematic>
      </link>
      <joint name='joint4' type='revolute'>
        <pose relative_to='joint_3_1'>0.02 -0.02 0.042626 0 -0 0</pose>
        <parent>joint_3_1</parent>
        <child>joint_4_1</child>
        <axis>
          <xyz>0 -1 0</xyz>
          <limit>
            <lower>-1.5708</lower>
            <upper>1.5708</upper>
            <effort>100</effort>
            <velocity>100</velocity>
          </limit>
          <dynamics>
            <damping>10</damping>
            <friction>200</friction>
            <spring_reference>0</spring_reference>
            <spring_stiffness>0</spring_stiffness>
          </dynamics>
        </axis>
      </joint>
      <link name='joint_4_1'>
        <pose relative_to='joint4'>0 0 0 0 -0 0</pose>
        <inertial>
          <pose>0.000193 -0.068641 0.001983 0 -0 0</pose>
          <mass>0.20509</mass>
          <inertia>
            <ixx>0.000453639</ixx>
            <ixy>2.65218e-06</ixy>
            <ixz>-3.94779e-07</ixz>
            <iyy>8.48057e-05</iyy>
            <iyz>-1.35826e-05</iyz>
            <izz>0.000507115</izz>
          </inertia>
        </inertial>
        <collision name='joint_4_1_collision'>
          <pose>0.005 0.037415 -0.27268 0 -0 0</pose>
          <geometry>
            <mesh>
              <scale>0.001 0.001 0.001</scale>
              <uri>model://industrial_robot_arm/meshes/joint_4_1.stl</uri>
            </mesh>
          </geometry>
          <max_contacts>10</max_contacts>
          <surface>
            <contact>
              <ode/>
            </contact>
            <bounce/>
            <friction>
              <torsional>
                <ode/>
              </torsional>
              <ode/>
            </friction>
          </surface>
        </collision>
        <collision name='joint_4_1_fixed_joint_lump__link_j4_j5_1_collision_1'>
          <pose>0.005 0.037415 -0.27268 0 -0 0</pose>
          <geometry>
            <mesh>
              <scale>0.001 0.001 0.001</scale>
              <uri>model://industrial_robot_arm/meshes/link_j4_j5_1.stl</uri>
            </mesh>
          </geometry>
          <max_contacts>10</max_contacts>
          <surface>
            <contact>
              <ode/>
            </contact>
            <bounce/>
            <friction>
              <torsional>
                <ode/>
              </torsional>
              <ode/>
            </friction>
          </surface>
        </collision>
        <visual name='joint_4_1_visual'>
          <pose>0.005 0.037415 -0.27268 0 -0 0</pose>
          <geometry>
            <mesh>
              <scale>0.001 0.001 0.001</scale>
              <uri>model://industrial_robot_arm/meshes/joint_4_1.stl</uri>
            </mesh>
          </geometry>
        </visual>
        <visual name='joint_4_1_fixed_joint_lump__link_j4_j5_1_visual_1'>
          <pose>0.005 0.037415 -0.27268 0 -0 0</pose>
          <geometry>
            <mesh>
              <scale>0.001 0.001 0.001</scale>
              <uri>model://industrial_robot_arm/meshes/link_j4_j5_1.stl</uri>
            </mesh>
          </geometry>
        </visual>
        <self_collide>0</self_collide>
        <enable_wind>0</enable_wind>
        <kinematic>0</kinematic>
      </link>
      <joint name='joint5' type='revolute'>
        <pose relative_to='joint_4_1'>-0.022 -0.15 0 0 -0 0</pose>
        <parent>joint_4_1</parent>
        <child>joint_5_6_1</child>
        <axis>
          <xyz>-1 0 0</xyz>
          <limit>
            <lower>-1.5708</lower>
            <upper>1.5708</upper>
            <effort>100</effort>
            <velocity>100</velocity>
          </limit>
          <dynamics>
            <damping>10</damping>
            <friction>200</friction>
            <spring_reference>0</spring_reference>
            <spring_stiffness>0</spring_stiffness>
          </dynamics>
        </axis>
      </joint>
      <link name='joint_5_6_1'>
        <pose relative_to='joint5'>0 0 0 0 -0 0</pose>
        <inertial>
          <pose>0.020773 -0.013442 5.1e-05 0 -0 0</pose>
          <mass>0.0342794</mass>
          <inertia>
            <ixx>1.6e-05</ixx>
            <ixy>0</ixy>
            <ixz>0</ixz>
            <iyy>1e-05</iyy>
            <iyz>0</iyz>
            <izz>1.9e-05</izz>
          </inertia>
        </inertial>
        <collision name='joint_5_6_1_collision'>
          <pose>0.027 0.187415 -0.27268 0 -0 0</pose>
          <geometry>
            <mesh>
              <scale>0.001 0.001 0.001</scale>
              <uri>model://industrial_robot_arm/meshes/joint_5_6_1.stl</uri>
            </mesh>
          </geometry>
          <max_contacts>10</max_contacts>
          <surface>
            <contact>
              <ode/>
            </contact>
            <bounce/>
            <friction>
              <torsional>
                <ode/>
              </torsional>
              <ode/>
            </friction>
          </surface>
        </collision>
        <visual name='joint_5_6_1_visual'>
          <pose>0.027 0.187415 -0.27268 0 -0 0</pose>
          <geometry>
            <mesh>
              <scale>0.001 0.001 0.001</scale>
              <uri>model://industrial_robot_arm/meshes/joint_5_6_1.stl</uri>
            </mesh>
          </geometry>
        </visual>
        <self_collide>0</self_collide>
        <enable_wind>0</enable_wind>
        <kinematic>0</kinematic>
      </link>
      <static>0</static>
      <plugin name='gazebo_ros2_control' filename='libgazebo_ros2_control.so'>
        <robotNamespace>/joint_trajectory_controller</robotNamespace>
        <parameters>/home/mogtaba/robotic_workspace/src/industrial_robot_arm/config/jtc.yaml</parameters>
      </plugin>
      <pose>0 0 0 0 -0 0</pose>
    </model>
    <state world_name='default'>
      <sim_time>194 80000000</sim_time>
      <real_time>461 330110700</real_time>
      <wall_time>1695918860 843652700</wall_time>
      <iterations>194080</iterations>
      <model name='arm'>
        <pose>0 0 -47945.9 0 -0 0</pose>
        <scale>1 1 1</scale>
        <link name='ground'>
          <pose>0 0 -47945.9 0 -0 0</pose>
          <velocity>-0 -0 -969.396 0 -0 0</velocity>
          <acceleration>-0 0 -9.8 0 -0 0</acceleration>
          <wrench>-0 0 -2.5103 0 -0 0</wrench>
        </link>
        <link name='joint_1_1'>
          <pose>0 0 -47945.8 0 -0 0</pose>
          <velocity>0 -0 -969.396 0 -0 0</velocity>
          <acceleration>0 0 -9.8 0 -0 0</acceleration>
          <wrench>0 0 -2.15863 0 -0 0</wrench>
        </link>
        <link name='joint_2_LEFT_1'>
          <pose>-0.035 -0.017415 -47945.8 0 -0 0</pose>
          <velocity>-0 -0 -969.396 0 -0 0</velocity>
          <acceleration>0 0 -9.8 0 -0 0</acceleration>
          <wrench>0 0 -1.33161 0 -0 0</wrench>
        </link>
        <link name='joint_3_1'>
          <pose>-0.025 -0.017415 -47945.6 0 -0 0</pose>
          <velocity>-0 -0 -969.396 0 -0 0</velocity>
          <acceleration>-0 -0 -9.8 0 -0 0</acceleration>
          <wrench>-0 -0 -0.704494 0 -0 0</wrench>
        </link>
        <link name='joint_4_1'>
          <pose>-0.005 -0.037415 -47945.6 0 -0 0</pose>
          <velocity>-0 0 -969.396 0 -0 0</velocity>
          <acceleration>-0 -0 -9.8 0 -0 0</acceleration>
          <wrench>-0 -0 -2.00988 0 -0 0</wrench>
        </link>
        <link name='joint_5_6_1'>
          <pose>-0.027 -0.187415 -47945.6 0 -0 0</pose>
          <velocity>0 -0 -969.396 0 -0 0</velocity>
          <acceleration>0 -0 -9.8 0 -0 0</acceleration>
          <wrench>0 -0 -0.335938 0 -0 0</wrench>
        </link>
      </model>
      <model name='ground_plane'>
        <pose>0 0 0 0 -0 0</pose>
        <scale>1 1 1</scale>
        <link name='link'>
          <pose>0 0 0 0 -0 0</pose>
          <velocity>0 0 0 0 -0 0</velocity>
          <acceleration>0 0 0 0 -0 0</acceleration>
          <wrench>0 0 0 0 -0 0</wrench>
        </link>
      </model>
      <light name='sun'>
        <pose>0 0 10 0 -0 0</pose>
      </light>
    </state>
    <gui fullscreen='0'>
      <camera name='user_camera'>
        <pose>2.91619 -3.05045 2.12511 0 0.275643 2.35619</pose>
        <view_controller>orbit</view_controller>
        <projection_type>perspective</projection_type>
      </camera>
    </gui>
  </world>
</sdf>
