<?xml version="1.0"?>
<robot xmlns:xacro="http://www.ros.org/wiki/xacro" name="industrial_robot_arm">
    <xacro:arg name="initial_positions_file" default="initial_positions.yaml" />
  <xacro:include filename="industrial_robot_arm_moveit.gazebo" />
    <link name="base_link">
    <inertial>
      <origin xyz="5.216616645949832e-07 -0.0006208121955855723 0.028742444807128353" rpy="0 0 0" />
      <mass value="0.25615293560955293" />
      <inertia ixx="0.000371" iyy="0.000377" izz="0.000587" ixy="-0.0" iyz="2e-06" ixz="0.0" />
    </inertial>
    <visual>
      <origin xyz="0 0 0" rpy="0 0 0" />
      <geometry>
        <mesh filename="package://industrial_robot_arm/meshes/base_link.stl"
          scale="0.001 0.001 0.001" />
      </geometry>
      <material name="white">
        <color rgba="1 1 1 1" />
        <!-- White color -->
      </material>
    </visual>
    <collision>
      <origin xyz="0 0 0" rpy="0 0 0" />
      <geometry>
        <mesh filename="package://industrial_robot_arm/meshes/base_link.stl"
          scale="0.001 0.001 0.001" />
      </geometry>
    </collision>
  </link>
  <link name="link1_1">
    <inertial>
      <origin xyz="-0.002640480430430652 0.002948913658327357 0.02573129664762941" rpy="0 0 0" />
      <mass value="0.22026782930399874" />
      <inertia ixx="0.000177" iyy="0.000243" izz="0.000255" ixy="-4e-06" iyz="4e-06" ixz="1.5e-05" />
    </inertial>
    <visual>
      <origin xyz="0.0 0.0 -0.05" rpy="0 0 0" />
      <geometry>
        <mesh filename="package://industrial_robot_arm/meshes/link1_1.stl" scale="0.001 0.001 0.001" />
      </geometry>
      <material name="white">
        <color rgba="1 1 1 1" />
        <!-- White color -->
      </material>
    </visual>
    <collision>
      <origin xyz="0.0 0.0 -0.05" rpy="0 0 0" />
      <geometry>
        <mesh filename="package://industrial_robot_arm/meshes/link1_1.stl" scale="0.001 0.001 0.001" />
      </geometry>
    </collision>
  </link>
  <link name="link2l_1">
    <inertial>
      <origin xyz="0.021957987083265868 2.1757363534782859e-07 0.003650506119877106" rpy="0 0 0" />
      <mass value="0.06932703471595757" />
      <inertia ixx="9.3e-05" iyy="9.1e-05" izz="1.3e-05" ixy="-0.0" iyz="0.0" ixz="2e-06" />
    </inertial>
    <visual>
      <origin xyz="0.013 0.017415 -0.144351" rpy="0 0 0" />
      <geometry>
        <mesh filename="package://industrial_robot_arm/meshes/link2l_1.stl"
          scale="0.001 0.001 0.001" />
      </geometry>
      <material name="white">
        <color rgba="1 1 1 1" />
        <!-- White color -->
      </material>
    </visual>
    <collision>
      <origin xyz="0.013 0.017415 -0.144351" rpy="0 0 0" />
      <geometry>
        <mesh filename="package://industrial_robot_arm/meshes/link2l_1.stl"
          scale="0.001 0.001 0.001" />
      </geometry>
    </collision>
  </link>
  <link name="link4a_1">
    <inertial>
      <origin xyz="-0.00375470433824487 -0.05737024902030902 0.0023877247705232363" rpy="0 0 0" />
      <mass value="0.1702875253703865" />
      <inertia ixx="0.00031" iyy="6.4e-05" izz="0.000348" ixy="-4.7e-05" iyz="-9e-06" ixz="-2e-06" />
    </inertial>
    <visual>
      <origin xyz="0.005 0.037415 -0.27268" rpy="0 0 0" />
      <geometry>
        <mesh filename="package://industrial_robot_arm/meshes/link4a_1.stl"
          scale="0.001 0.001 0.001" />
      </geometry>
      <material name="white">
        <color rgba="1 1 1 1" />
        <!-- White color -->
      </material>
    </visual>
    <collision>
      <origin xyz="0.005 0.037415 -0.27268" rpy="0 0 0" />
      <geometry>
        <mesh filename="package://industrial_robot_arm/meshes/link4a_1.stl"
          scale="0.001 0.001 0.001" />
      </geometry>
    </collision>
  </link>
  <link name="link4b_1">
    <inertial>
      <origin xyz="0.019510506404598008 -0.027788188164522387 -0.013999962432383606" rpy="0 0 0" />
      <mass value="0.03480265269587224" />
      <inertia ixx="1.6e-05" iyy="5e-06" izz="1.6e-05" ixy="5e-06" iyz="0.0" ixz="0.0" />
    </inertial>
    <visual>
      <origin xyz="0.005 0.133415 -0.28668" rpy="0 0 0" />
      <geometry>
        <mesh filename="package://industrial_robot_arm/meshes/link4b_1.stl"
          scale="0.001 0.001 0.001" />
      </geometry>
      <material name="white">
        <color rgba="1 1 1 1" />
        <!-- White color -->
      </material>
    </visual>
    <collision>
      <origin xyz="0.005 0.133415 -0.28668" rpy="0 0 0" />
      <geometry>
        <mesh filename="package://industrial_robot_arm/meshes/link4b_1.stl"
          scale="0.001 0.001 0.001" />
      </geometry>
    </collision>
  </link>
  <link name="link5_1">
    <inertial>
      <origin xyz="0.020772844274120555 -0.013441807562935087 5.0717953016810036e-05" rpy="0 0 0" />
      <mass value="0.034279369968409995" />
      <inertia ixx="1.6e-05" iyy="1e-05" izz="1.9e-05" ixy="-0.0" iyz="-0.0" ixz="0.0" />
    </inertial>
    <visual>
      <origin xyz="0.027 0.187415 -0.27268" rpy="0 0 0" />
      <geometry>
        <mesh filename="package://industrial_robot_arm/meshes/link5_1.stl" scale="0.001 0.001 0.001" />
      </geometry>
      <material name="white">
        <color rgba="1 1 1 1" />
        <!-- White color -->
      </material>
    </visual>
    <collision>
      <origin xyz="0.027 0.187415 -0.27268" rpy="0 0 0" />
      <geometry>
        <mesh filename="package://industrial_robot_arm/meshes/link5_1.stl" scale="0.001 0.001 0.001" />
      </geometry>
    </collision>
  </link>
  <link name="link2r_1">
    <inertial>
      <origin xyz="0.014921423807845498 2.0000166528477692e-07 0.04415294138852767" rpy="0 0 0" />
      <mass value="0.06655205069580611" />
      <inertia ixx="0.000148" iyy="0.000142" izz="9e-06" ixy="-0.0" iyz="-0.0" ixz="-3e-06" />
    </inertial>
    <visual>
      <origin xyz="0.035 0.017415 -0.110054" rpy="0 0 0" />
      <geometry>
        <mesh filename="package://industrial_robot_arm/meshes/link2r_1.stl"
          scale="0.001 0.001 0.001" />
      </geometry>
      <material name="white">
        <color rgba="1 1 1 1" />
        <!-- White color -->
      </material>
    </visual>
    <collision>
      <origin xyz="0.035 0.017415 -0.110054" rpy="0 0 0" />
      <geometry>
        <mesh filename="package://industrial_robot_arm/meshes/link2r_1.stl"
          scale="0.001 0.001 0.001" />
      </geometry>
    </collision>
  </link>
  <link name="link3_1">
    <inertial>
      <origin xyz="0.022122141024786626 0.005605069297118697 0.03722389505778892" rpy="0 0 0" />
      <mass value="0.07188709477669679" />
      <inertia ixx="5.4e-05" iyy="4.2e-05" izz="4.2e-05" ixy="-1e-06" iyz="-3e-06" ixz="-2e-06" />
    </inertial>
    <visual>
      <origin xyz="0.025 0.017415 -0.230054" rpy="0 0 0" />
      <geometry>
        <mesh filename="package://industrial_robot_arm/meshes/link3_1.stl" scale="0.001 0.001 0.001" />
      </geometry>
      <material name="white">
        <color rgba="1 1 1 1" />
        <!-- White color -->
      </material>
    </visual>
    <collision>
      <origin xyz="0.025 0.017415 -0.230054" rpy="0 0 0" />
      <geometry>
        <mesh filename="package://industrial_robot_arm/meshes/link3_1.stl" scale="0.001 0.001 0.001" />
      </geometry>
    </collision>
  </link>
  <link name="gripper_1">
    <inertial>
      <origin xyz="-4.09654948851923e-15 -0.00149979999999722 -9.999999750487376e-08" rpy="0 0 0" />
      <mass value="0.004087644009105276" />
      <inertia ixx="0.0" iyy="0.0" izz="0.0" ixy="0.0" iyz="0.0" ixz="-0.0" />
    </inertial>
    <visual>
      <origin xyz="0.00625 0.225415 -0.27268" rpy="0 0 0" />
      <geometry>
        <mesh filename="package://industrial_robot_arm/meshes/gripper_1.stl"
          scale="0.001 0.001 0.001" />
      </geometry>
      <material name="white">
        <color rgba="1 1 1 1" />
        <!-- White color -->
      </material>
    </visual>
    <collision>
      <origin xyz="0.00625 0.225415 -0.27268" rpy="0 0 0" />
      <geometry>
        <mesh filename="package://industrial_robot_arm/meshes/gripper_1.stl"
          scale="0.001 0.001 0.001" />
      </geometry>
    </collision>
  </link>

  <joint name="joint1" type="revolute">
    <origin xyz="0.0 0.0 0.05" rpy="0 0 0" />
    <parent link="base_link" />
    <child link="link1_1" />
    <axis xyz="-0.0 -0.0 1.0" />
    <limit upper="1.570796" lower="-1.570796" effort="100" velocity="100" />
  </joint>
  <joint name="joint2" type="revolute">
    <origin xyz="-0.035 -0.017415 0.060054" rpy="0 0 0" />
    <parent link="link1_1" />
    <child link="link2r_1" />
    <axis xyz="-1.0 0.0 0.0" />
    <limit upper="1.570796" lower="-1.570796" effort="100" velocity="100" />
  </joint>
  <joint name="joint3" type="revolute">
    <origin xyz="0.01 0.0 0.12" rpy="0 0 0" />
    <parent link="link2r_1" />
    <child link="link3_1" />
    <axis xyz="-1.0 0.0 0.0" />
    <limit upper="1.570796" lower="-1.570796" effort="100" velocity="100" />
  </joint>
  <joint name="joint4" type="revolute">
    <origin xyz="0.02 -0.02 0.042626" rpy="0 0 0" />
    <parent link="link3_1" />
    <child link="link4a_1" />
    <axis xyz="-0.0 -1.0 0.0" />
    <limit upper="1.570796" lower="-1.570796" effort="100" velocity="100" />
  </joint>
  <joint name="joint5" type="revolute">
    <origin xyz="-0.022 -0.15 0.0" rpy="0 0 0" />
    <parent link="link4a_1" />
    <child link="link5_1" />
    <axis xyz="-1.0 -0.0 0.0" />
    <limit upper="1.570796" lower="-1.570796" effort="100" velocity="100" />
  </joint>
  <joint name="joint6" type="revolute">
    <origin xyz="0.02075 -0.038 0.0" rpy="0 0 0" />
    <parent link="link5_1" />
    <child link="gripper_1" />
    <axis xyz="0.0 -1.0 0.0" />
    <limit upper="3.141593" lower="0.0" effort="100" velocity="100" />
  </joint>
  <joint name="fixed1" type="fixed">
    <origin xyz="0.022 0.0 0.034297" rpy="0 0 0" />
    <parent link="link2r_1" />
    <child link="link2l_1" />
  </joint>
  <joint name="fixed2" type="fixed">
    <origin xyz="0.0 -0.096 0.014" rpy="0 0 0" />
    <parent link="link4a_1" />
    <child link="link4b_1" />
  </joint>


    <!-- Import control_xacro -->
    <xacro:include filename="industrial_robot_arm.ros2_control.xacro" />


    <xacro:industrial_robot_arm_ros2_control name="FakeSystem" initial_positions_file="$(arg initial_positions_file)"/>

</robot>
